<?xml version="1.0"?>
<!-- Open_Manipulator Chain -->
<robot name="omx_inno" xmlns:xacro="http://ros.org/wiki/xacro">

  <!-- Include tb3_inno URDF -->
  <xacro:include filename="$(find tb3_inno_description)/urdf/tb3_inno.urdf.xacro" />

  <!-- Include OpenManipulator Chain Gazebo Parameter -->
  <!-- <xacro:include filename="$(find tb3_inno_description)/urdf/omx_inno.gazebo.xacro" /> -->

  <!-- Transmission macro -->
  <xacro:macro name="SimpleTransmission" params="joint n">
    <transmission name="tran${n}">
      <type>transmission_interface/SimpleTransmission</type>
      <joint name="${joint}">
        <hardwareInterface>hardware_interface/PositionJointInterface</hardwareInterface>
      </joint>
      <actuator name="motor${n}">
        <hardwareInterface>hardware_interface/PositionJointInterface</hardwareInterface>
        <mechanicalReduction>1</mechanicalReduction>
      </actuator>
    </transmission>
  </xacro:macro>

  <!-- Base fixed joint -->
  <joint name="base_fixed" type="fixed">
    <origin xyz="0.0 0.0 0.1405" rpy="0 0 0"/>
    <parent link="base_link"/>
    <child link="link1"/>
  </joint>

  <!-- Link 1 -->
  <link name="link1">
    <visual>
      <origin xyz="0 0 0" rpy="0 0 0"/>
      <geometry>
        <mesh filename="package://tb3_inno_description/meshes/omx_rx0ii_link1.stl" scale="0.001 0.001 0.001"/>
      </geometry>
      <material name="grey"/>
    </visual>

    <collision>
      <origin xyz="0 0 0" rpy="0 0 0"/>
      <geometry>
        <mesh filename="package://tb3_inno_description/meshes/omx_rx0ii_link1.stl" scale="0.001 0.001 0.001"/>
      </geometry>
    </collision>

    <inertial>
      <origin xyz="0 0 0" />
      <mass value="0.017" />
      <inertia ixx="0.001" ixy="0.0" ixz="0.0"
               iyy="0.001" iyz="0.0"
               izz="0.001" />
    </inertial>

    <!-- <inertial> -->
    <!--   <origin xyz="0.0 0.0 0.0" /> -->
    <!--   <mass value="7.9119962e-02" /> -->
    <!--   <inertia ixx="1.2505234e-05" ixy="0.0" ixz="-1.7855208e-07" -->
    <!--            iyy="2.1898364e-05" iyz="0.0" -->
    <!--            izz="1.9267361e-05" /> -->
    <!-- </inertial> -->
  </link>

  <!-- Joint 1 -->
  <joint name="joint1" type="revolute">
    <parent link="link1"/>
    <child link="link2"/>
    <origin xyz="0.0 0.0 0.036" rpy="0 0 0"/>
    <axis xyz="0 0 1"/>
    <limit velocity="4.8" effort="1" lower="${-pi*0.9}" upper="${pi*0.9}" />
  </joint>

  <!-- Transmission 1 -->
  <xacro:SimpleTransmission n="1" joint="joint1" />

  <!--  Link 2 -->
  <link name="link2">
    <visual>
      <origin xyz="0 0 0.0" rpy="0 0 0"/>
      <geometry>
        <mesh filename="package://tb3_inno_description/meshes/omx_rx0ii_link2.stl" scale="0.001 0.001 0.001"/>
      </geometry>
      <material name="grey"/>
    </visual>

    <collision>
      <origin xyz="0 0 0.0" rpy="0 0 0"/>
      <geometry>
        <mesh filename="package://tb3_inno_description/meshes/omx_rx0ii_link2.stl" scale="0.001 0.001 0.001"/>
      </geometry>
    </collision>

    <inertial>
      <origin xyz="0 0 0" />
      <mass value="0.017" />
      <inertia ixx="0.001" ixy="0.0" ixz="0.0"
               iyy="0.001" iyz="0.0"
               izz="0.001" />
    </inertial>

    <!-- <inertial> -->
    <!--   <origin xyz="0.0 0.0 0.0" /> -->
    <!--   <mass value="9.8406837e-02" /> -->
    <!--   <inertia ixx="3.4543422e-05" ixy="-1.6031095e-08" ixz="-3.8375155e-07" -->
    <!--            iyy="3.2689329e-05" iyz="2.8511935e-08" -->
    <!--            izz="1.8850320e-05" /> -->
    <!-- </inertial> -->
  </link>

  <!--  Joint 2 -->
  <joint name="joint2" type="revolute">
    <parent link="link2"/>
    <child link="link3"/>
    <origin xyz="0.0 0.019 0.0405" rpy="0 0 0"/>
    <axis xyz="0 1 0"/>
    <limit velocity="4.8" effort="1" lower="${-pi*0.57}" upper="${pi*0.5}" />
  </joint>

  <!-- Transmission 2 -->
  <xacro:SimpleTransmission n="2" joint="joint2" />

  <!--  Link 3 -->
  <link name="link3">
    <visual>
      <origin xyz="0 0 0" rpy="0 0 0"/>
      <geometry>
        <mesh filename="package://tb3_inno_description/meshes/omx_rx0ii_link3.stl" scale="0.001 0.001 0.001"/>
      </geometry>
      <material name="grey"/>
    </visual>

    <collision>
      <origin xyz="0 0 0" rpy="0 0 0"/>
      <geometry>
        <mesh filename="package://tb3_inno_description/meshes/omx_rx0ii_link3.stl" scale="0.001 0.001 0.001"/>
      </geometry>
    </collision>

  <!--    <inertial>
      <origin xyz="0 0 0" />
      <mass value="0.136" />
      <inertia ixx="0.1" ixy="0.0" ixz="0.0"
               iyy="0.1" iyz="0.0"
               izz="0.1" />
    </inertial>-->

    <inertial>
      <origin xyz="0 0 0" />
      <mass value="0.017" />
      <inertia ixx="0.001" ixy="0.0" ixz="0.0"
               iyy="0.001" iyz="0.0"
               izz="0.001" />
    </inertial>

    <!-- <inertial> -->
    <!--   <origin xyz="0.0 0.0 0.0" /> -->
    <!--   <mass value="1.3850917e-01" /> -->
    <!--   <inertia ixx="3.3055381e-04" ixy="-9.7940978e-08" ixz="-3.8505711e-05" -->
    <!--            iyy="3.4290447e-04" iyz="-1.5717516e-06" -->
    <!--            izz="6.0346498e-05" /> -->
    <!-- </inertial> -->
  </link>

  <!--  Joint 3 -->
  <joint name="joint3" type="revolute">
    <parent link="link3"/>
    <child link="link4"/>
    <origin xyz="0.024 0 0.128" rpy="0 0 0"/>
    <axis xyz="0 1 0"/>
    <limit velocity="4.8" effort="1" lower="${-pi*0.3}" upper="${pi*0.44}" />
  </joint>

  <!-- Transmission 3 -->
  <xacro:SimpleTransmission n="3" joint="joint3" />

  <!-- <!-\-  Link 4 -\-> -->
  <link name="link4">
    <visual>
      <origin xyz="0 0 0" rpy="0 0 0"/>
      <geometry>
        <mesh filename="package://tb3_inno_description/meshes/omx_rx0ii_link4.stl" scale="0.001 0.001 0.001"/>
      </geometry>
      <material name="grey"/>
    </visual>

    <collision>
      <origin xyz="0 0 0" rpy="0 0 0"/>
      <geometry>
        <mesh filename="package://tb3_inno_description/meshes/omx_rx0ii_link4.stl" scale="0.001 0.001 0.001"/>
      </geometry>
    </collision>

  <!--    <inertial>
      <origin xyz="0 0 0" />
      <mass value="0.131" />
      <inertia ixx="0.1" ixy="0.0" ixz="0.0"
               iyy="0.1" iyz="0.0"
               izz="0.1" />
    </inertial>-->

    <inertial>
      <origin xyz="0 0 0" />
      <mass value="0.017" />
      <inertia ixx="0.001" ixy="0.0" ixz="0.0"
               iyy="0.001" iyz="0.0"
               izz="0.001" />
    </inertial>

    <!--  <inertial> -->
    <!--   <origin xyz="0 0 0" /> -->
    <!--   <mass value="1.3274562e-01" /> -->
    <!--   <inertia ixx="3.0654178e-05" ixy="-1.2764155e-06" ixz="-2.6874417e-07" -->
    <!--            iyy="2.4230292e-04" iyz="1.1559550e-08" -->
    <!--            izz="2.5155057e-04" /> -->
    <!-- </inertial> -->
  </link>

  <!--  Joint 4 -->
  <joint name="joint4" type="revolute">
    <parent link="link4"/>
    <child link="link5"/>
    <origin xyz="0.124 0.0 0.0" rpy="0 0 0"/>
    <axis xyz="0 1 0"/>
    <limit velocity="4.8" effort="1" lower="${-pi*0.57}" upper="${pi*0.65}" />
  </joint>

  <!-- Transmission 4 -->
  <xacro:SimpleTransmission n="4" joint="joint4" />

  <!--  Link 5 -->
  <link name="link5">
    <visual>
      <origin xyz="0 0 0" rpy="0 0 0"/>
      <geometry>
        <mesh filename="package://tb3_inno_description/meshes/omx_rx0ii_link5.stl" scale="0.001 0.001 0.001"/>
      </geometry>
      <material name="grey"/>
    </visual>

    <collision>
      <origin xyz="0 0 0" rpy="0 0 0"/>
      <geometry>
        <mesh filename="package://tb3_inno_description/meshes/omx_rx0ii_link5.stl" scale="0.001 0.001 0.001"/>
      </geometry>
    </collision>

  <!--    <inertial>
      <origin xyz="0 0 0" />
      <mass value="0.141" />
      <inertia ixx="0.1" ixy="0.0" ixz="0.0"
               iyy="0.1" iyz="0.0"
               izz="0.1" />
    </inertial>-->

    <inertial>
      <origin xyz="0 0 0" />
      <mass value="0.017" />
      <inertia ixx="0.001" ixy="0.0" ixz="0.0"
               iyy="0.001" iyz="0.0"
               izz="0.001" />
    </inertial>
    
    <!-- <inertial> -->
    <!--   <origin xyz="0.0 0.0 0.0" /> -->
    <!--   <mass value="1.4327573e-01" /> -->
    <!--   <inertia ixx="8.0870749e-05" ixy="0.0" ixz="-1.0157896e-06" -->
    <!--            iyy="7.5980465e-05" iyz="0.0" -->
    <!--            izz="9.3127351e-05" /> -->
    <!-- </inertial> -->
  </link>

  <!--  Joint 5 -->
  <joint name="link5" type="revolute">
    <parent link="link5"/>
    <child link="link6"/>
    <origin xyz="0.028 -0.019 0.0" rpy="0 0 0"/>
    <axis xyz="1 0 0"/>
    <limit velocity="4.8" effort="1" lower="${-pi*1.0}" upper="${pi*1.0}" />
  </joint>

  <!-- Transmission 5 -->
  <xacro:SimpleTransmission n="5" joint="joint5" />

  <!-- Link 6  -->
  <link name="link6">
    <visual>
      <origin xyz="0.0 0.0 0" rpy="0 0 0"/>
      <geometry>
        <mesh filename="package://tb3_inno_description/meshes/omx_rx0ii_link6.stl" scale="0.001 0.001 0.001"/>
      </geometry>
      <material name="grey"/>
    </visual>

    <collision>
      <origin xyz="0.0 0.0 0" rpy="0 0 0"/>
      <geometry>
        <mesh filename="package://tb3_inno_description/meshes/omx_rx0ii_link6.stl" scale="0.001 0.001 0.001"/>
      </geometry>
    </collision>

    <inertial>
      <origin xyz="0 0 0" />
      <mass value="0.017" />
      <inertia ixx="0.001" ixy="0.0" ixz="0.0"
               iyy="0.001" iyz="0.0"
               izz="0.001" />
    </inertial>

    <!-- <inertial> -->
    <!--   <origin xyz="0 0 0" /> -->
    <!--   <mass value="0.017" /> -->
    <!--   <inertia ixx="0.001" ixy="0.0" ixz="0.0" -->
    <!--            iyy="0.001" iyz="0.0" -->
    <!--            izz="0.001" /> -->
    <!-- </inertial> -->

    <!--     <inertial>
      <origin xyz="${0.028 + 8.3720668e-03} ${0.0246 + 9.9696160e-03} -4.2836895e-07" />
      <mass value="3.2218127e-02" />
      <inertia ixx="9.5568826e-06" ixy="2.8424644e-06" ixz="-3.2829197e-10"
               iyy="2.2552871e-05" iyz="-3.1463634e-10"
               izz="1.7605306e-05" />
    </inertial>-->
  </link>

  <!-- Camera joint -->
  <joint name="camera_link_joint" type="fixed">
    <origin xyz="0.0765 0.0 0.0" rpy="0 0 0"/>
    <parent link="link6"/>
    <child link="camera_link"/>
  </joint>

  <link name="camera_link" />

  <joint name="camera_color_joint" type="fixed">
    <origin xyz="0.0 0.0 0.0" rpy="0 0 0"/>
    <parent link="camera_link"/>
    <child link="camera_color_frame"/>
  </joint>

  <link name="camera_color_frame" />

  <joint name="camera_color_optical_joint" type="fixed">
    <origin xyz="0 0 0" rpy="${-pi/2} 0 ${-pi/2}" />
    <parent link="camera_color_frame" />
    <child link="camera_color_optical_frame" />
  </joint>

  <link name="camera_color_optical_frame"/>

  <!-- <!-\- end effector link -\-> -->
  <!-- <link name="end_effector_link"> -->
  <!--   <visual> -->
  <!--     <origin xyz="0 0 0" rpy="0 0 0"/> -->
  <!--     <geometry> -->
  <!--       <box size="0.01 0.01 0.01" /> -->
  <!--     </geometry> -->
  <!--     <material name="red"/> -->
  <!--    </visual> -->

  <!--   <inertial> -->
  <!--     <origin xyz="0.0 0.0 0.0" rpy="0 0 0"/> -->
  <!--     <mass value="0.001"/> -->
  <!--     <inertia ixx="0.001" ixy="0.0" ixz="0.0" iyy="0.001" iyz="0.0" izz="0.001" /> -->
  <!--   </inertial> -->
  <!-- </link> -->

</robot>

